<mujoco model="ant">
  <compiler angle="degree" coordinate="local" inertiafromgeom="true"/>
  <asset>
    <!-- <texture name="skybox" type="skybox" builtin="flat" rgb1="1 1 1" width="800" height="800" /> -->
    <texture name="grid" type="2d" builtin="flat" rgb1="0.8 0.8 0.8" width="300" height="300" mark="edge"/>
    <material name="grid" texture="grid"/>
    <material name="self" rgba=".7 .5 .3 1"/>
    <texture name="skybox" type="skybox" builtin="gradient" rgb1=".2 .3 .4" rgb2="0 0 0" width="800" height="800" mark="random" markrgb="1 1 1"/>
  </asset>
  <visual>
    <headlight ambient=".4 .4 .4" diffuse=".8 .8 .8" specular="0.1 0.1 0.1"/>
    <map znear=".001"/>
  </visual>
    <!-- <option integrator="RK4" timestep="0.01"/> -->
  <default>
      <joint armature="1" damping="1" limited="true"/>
      <geom conaffinity="0" condim="3" density="5.0" friction="1 0.5 0.5" margin="0.01" rgba=".7 .5 .3 1"/>
  </default>
  <worldbody>
    <light cutoff="100" diffuse="1 1 1" dir="0 -0.5 -1.3" directional="true" exponent="1" pos="0 50 130" specular=".1 .1 .1"/>
    <geom name='floor1' material="grid" pos='26 0 0' type='hfield' conaffinity='1' rgba="0.2 0.2 0.2 1" condim='3' hfield="floor"/>
    <body name="0" pos="0 0 0.75">
      <camera name="track" mode="trackcom" pos="0 -3 0.3" xyaxes="1 0 0 0 0 1"/>
      <!-- <geom name="0" pos="0 0 0" size="0.15" type="sphere"/> -->
      <geom fromto="0.0 0.0 0.0 0.2 0.2 0.0" name="body_0_geom" size="0.04" type="capsule"/>
      <joint armature="0" damping="0" limited="false" margin="0.01" name="root" pos="0 0 0" type="free"/>
      <body name="1" pos="0.2 0.2 0">
        <geom fromto="0.0 0.0 0.0 0.2 0.2 0.0" name="body_1_geom" size="0.08" type="capsule"/>
        <joint axis="-0.707 0.707 0" name="body_1" pos="0.0 0.0 0.0" limited="true" range="-100 100" type="hinge"/>
      </body>
      <!-- <body name="2" pos="0.2 0.2 0">
        <geom fromto="0.0 0.0 0.0 -0.2 -0.2 0.0" name="body_2_geom" size="0.08" type="capsule"/>
        <joint axis="0 1 0" name="body_2" pos="0.0 0.0 0.0" limited="true" range="-100 100" type="hinge"/>
      </body> -->
    </body>
  </worldbody>
  <actuator>
    <motor ctrllimited="true" ctrlrange="-1.0 1.0" joint="body_1" gear="150"/>
    <!-- <motor ctrllimited="true" ctrlrange="-1.0 1.0" joint="body_2" gear="150"/> -->
  </actuator>
  <asset>
    <texture type="skybox" builtin="gradient" rgb1=".4 .5 .6" rgb2="0 0 0" width="100" height="100"/>
    <texture builtin="flat" height="1278" mark="cross" markrgb="1 1 1" name="texgeom" random="0.01" rgb1="0.8 0.6 0.4" rgb2="0.8 0.6 0.4" type="cube" width="127"/>
    <texture builtin="checker" height="100" name="texplane" rgb1="0 0 0" rgb2="0.8 0.8 0.8" type="2d" width="100"/>
    <material name="MatPlane" reflectance="0.5" shininess="1" specular="1" texrepeat="60 60" texture="texplane"/>
    <material name="geom" texture="texgeom" texuniform="true"/>
    <hfield name="floor" size = "32 32 0.05 0.1" file="./gap_terrain.png"/>
    <texture name="grid_new" type="2d" builtin="checker" rgb1=".1 .3 .2" rgb2=".2 .4 .3" width="1000" height="100" mark="none" markrgb=".8 .6 .4"/>
    <material name="grid_new" texture="grid_new" texrepeat="0.0 0.2" texuniform="true" reflectance=".2"/>
  </asset>
</mujoco>